Workbook

Sheet Instrucciones
A1: Planta piloto de cerveza — Balance de materia y energía
A2: Insumo y complemento para simular en DWSIM · sin TACC y sin alcohol (≤0,5 % v/v) · fermentador de 600 L
B4: Cómo usar esta planilla
B6: • Esta planilla no reemplaza a DWSIM: es el cálculo a mano que vas verificando en paralelo, equipo por equipo, tal como pide la guía ("Qué entregar").
B7: • Cada pestaña corresponde a una sección de la guía: Balance de materia, Bomba, Intercambiador y Fermentador. La última pestaña (Comparación) junta los resultados de las cuatro para el entregable final.
B8: • Las celdas en color CREMA con texto azul son las que completás vos (datos de tu receta o resultados que te da DWSIM). El resto son fórmulas — no las edites, se recalculan solas.
B9: • El balance de materia se calcula hacia atrás a partir del volumen del fermentador (celda B6 de la pestaña Balance de materia, 600 L por defecto): cambiá ese único dato y toda la planilla se recalcula sola, sin perder la coherencia entre las corrientes.
B11: Referencia de colores
B13: Dato que completás vos (input) | C13: ej: 650
B14: Resultado calculado (fórmula, no tocar) | C14: =3+4 -> 7
B15: Encabezado de sección
B17: Pestañas de esta planilla
B19: Balance de materia | C19: Escalado de la malta, reparto en maltosa/glucosa, entradas conocidas y cierre del balance con los resultados que te da DWSIM.
B20: Bomba | C20: Cálculo manual de trabajo, ΔT, potencia y NPSH — mismo ejemplo numérico de la guía, con tus propios valores.
B21: Intercambiador | C21: Calor a retirar del mosto y potencia de refrigeración según el tiempo de enfriado que elijas.
B22: Fermentador | C22: El cálculo de diseño: qué % de conversión cargar en el reactor de DWSIM para llegar a ≤0,5 % v/v.
B23: Comparación DWSIM | C23: Tabla resumen: tu cálculo manual vs. el resultado de DWSIM en cada equipo, con el % de diferencia — para el entregable final.
B25: Guía completa: profe.lemeit.ar/notes/lab-industrias-7mo/ — sección 2 (Balance de materia), 4 (Bomba), 5 (Intercambiador), 6 (Fermentador).

Sheet Balance de materia
A1: Balance de materia del proceso
A2: Calculado hacia atrás desde el volumen del fermentador — cierra por construcción
A4: Punto de partida: el fermentador
A6: Variable | B6: Valor | C6: Unidad | D6: Nota
A7: Volumen del fermentador | B7: 600 | C7: L | D7: El dato de equipo que fija todo el balance — pensado para el resto de la planta y el cálculo de costos
A8: Concentración de azúcar en el mosto | B8: 0.1 | C8: — | D8: Mosto de fuerza moderada, se va a fermentar poco de todas formas
A9: ρ mosto (densidad) | B9: 1 | C9: kg/L
A10: Azúcar total = Vol × conc. × ρ | B10: =B7*B8*B9 -> 60 | C10: kg
A12: Split maltosa / glucosa (hidrólisis del almidón)
A14: Variable | B14: Valor | C14: Unidad | D14: Nota
A15: % maltosa (del azúcar total) | B15: 0.83 | C15: — | D15: Córdova, ESPOCH (2021)
A16: % glucosa = 1 − % maltosa | B16: =1-B15 -> 0.17
A17: Maltosa | B17: =B10*B15 -> 49.8 | C17: kg | D17: Va al campo 'maltose' del reactor en DWSIM
A18: Glucosa | B18: =B10*B16 -> 10.2 | C18: kg | D18: Va al campo 'Glucose' del reactor en DWSIM
A20: Malta y agua de maceración
A22: Variable | B22: Valor | C22: Unidad | D22: Nota
A23: % almidón extraíble (de la malta) | B23: 0.58 | C23: — | D23: El resto — proteínas, cáscara, dextrinas — no fermenta, sale como bagazo o queda de cuerpo
A24: Malta necesaria = azúcar total / % almidón | B24: =B10/B23 -> 103.44828 | C24: kg
A25: Relación agua / malta | B25: 3 | C25: L/kg
A26: Agua de macerado = malta × relación | B26: =B24*B25 -> 310.34483 | C26: kg
A28: Agua de relleno antes del hervor
A30: Variable | B30: Valor | C30: Unidad | D30: Nota
A31: % de agua que se evapora en el hervor | B31: 0.1 | C31: —
A32: Agua final en el mosto frío (= Vol·ρ − azúcares) | B32: =B7*B9-B10 -> 540 | C32: kg
A33: Agua total antes del hervor = agua final / (1 − % evap.) | B33: =B32/(1-B31) -> 600 | C33: kg
A34: Agua de hervido (relleno) = agua total − agua macerado | B34: =B33-B26 -> 289.65517 | C34: kg
A36: Entradas conocidas
A38: Corriente | B38: Cantidad (kg) | D38: Nota
A39: Malta (sin TACC) | B39: =B24 -> 103.44828
A40: Agua de macerado | B40: =B26 -> 310.34483
A41: Agua de hervido (relleno) | B41: =B34 -> 289.65517
A42: Enzimas | B42: 0.1 | D42: ≈0,10 kg — completá con tu receta si tenés un dato más preciso
A43: Levadura + agua de inóculo | B43: 0 | D43: Completá con tu receta
A44: Lúpulo | B44: 0 | D44: Completá con tu receta
A45: Agente clarificante | B45: 0 | D45: Completá con tu receta
A46: TOTAL ENTRADAS CONOCIDAS | B46: =SUM(B39:B45) -> 703.54828
A48: Salidas — completá con el resultado de DWSIM
A50: Corriente | C50: DWSIM (kg) | D50: Nota
A51: Bagazo 1 (filtro) | C51: 0
A52: Vapor (hervor) | C52: 0
...

Sheet Bomba
A1: Primer equipo: la bomba
A2: Trabajo, ΔT, potencia y NPSH — mismo cálculo que 'Qué calcula DWSIM por dentro'
A4: Datos de la corriente y de la bomba
A6: Variable | B6: Valor | C6: Unidad | D6: Nota
A7: ΔP (aumento de presión) | B7: 100000 | C7: Pa
A8: η (eficiencia de la bomba) | B8: 0.72 | C8: —
A9: ρ (densidad del líquido) | B9: 998 | C9: kg/m³
A10: Cₚ (calor específico) | B10: 4.186 | C10: kJ/kg·K
A11: ṁ (caudal másico) | B11: 0.5 | C11: kg/s
A12: P₁ (presión de succión) | B12: 101325 | C12: Pa
A13: P_burbuja (presión de vapor a T₁) | B13: 2339 | C13: Pa | D13: Tomalo del flash de punto de burbuja en DWSIM (o de tablas de vapor a T₁)
A15: Cálculo manual
A17: Resultado | B17: Valor | C17: Unidad | D17: Fórmula
A18: w_ideal = ΔP / ρ | B18: =B7/B9/1000 -> 0.1002004 | C18: kJ/kg
A19: w_real = w_ideal / η | B19: =B18/B8 -> 0.13916722 | C19: kJ/kg
A20: ΔT = (w_real − w_ideal) / Cₚ | B20: =(B19-B18)/B10 -> 0.0093088444 | C20: °C
A21: Power = ṁ · w_real | B21: =B11*B19 -> 0.069583612 | C21: kW
A22: Head = ΔP / (ρ · g) | B22: =B7/(B9*9.81) -> 10.214108 | C22: m
A23: NPSH = (P₁ − P_burbuja) / (ρ · g) | B23: =(B12-B13)/(B9*9.81) -> 10.110537 | C23: m
A25: Comparación contra DWSIM
A27: Resultado | B27: Manual | C27: DWSIM | D27: % diferencia
A28: ΔT (°C) | B28: =B20 -> 0.0093088444 | C28: 0 | D28: =IF(C28=0,"",IFERROR((C28-B28)/B28,""))
A29: Power (kW) | B29: =B21 -> 0.069583612 | C29: 0 | D29: =IF(C29=0,"",IFERROR((C29-B29)/B29,""))
A30: NPSH (m) | B30: =B23 -> 10.110537 | C30: 0 | D30: =IF(C30=0,"",IFERROR((C30-B30)/B30,""))

Sheet Intercambiador
A1: Segundo equipo: el intercambiador
A2: Calor a retirar del mosto y potencia de refrigeración
A4: Datos de la corriente
A6: Variable | B6: Valor | C6: Unidad | D6: Nota
A7: ṁ (caudal del mosto) | B7: 600 | C7: kg | D7: Mosto-4 de la guía: 600,0 kg para un fermentador de 600 L
A8: Cₚ (calor específico del mosto) | B8: 4 | C8: kJ/kg·K | D8: El mosto es ~90% agua
A9: T₁ (temperatura de entrada) | B9: 100 | C9: °C
A10: T₂ (temperatura de salida) | B10: 20 | C10: °C
A11: Tiempo de enfriado elegido | B11: 30 | C11: min
A13: Cálculo manual
A15: Resultado | B15: Valor | C15: Unidad | D15: Fórmula
A16: ΔT = T₁ − T₂ | B16: =B9-B10 -> 80 | C16: °C
A17: Q = ṁ · Cₚ · ΔT | B17: =B7*B8*B16 -> 192000 | C17: kJ
A18: Q en kWh | B18: =B17/3600 -> 53.333333 | C18: kWh
A19: Potencia de refrigeración = Q / tiempo | B19: =B17/(B11*60) -> 106.66667 | C19: kW
A21: Comparación contra DWSIM
A23: Resultado | B23: Manual | C23: DWSIM (Heat Removed) | D23: % diferencia
A24: Calor retirado (kJ, equivalente) | B24: =B17 -> 192000 | C24: 0 | D24: =IF(C24=0,"",IFERROR((C24-B24)/B24,""))

Sheet Fermentador
A1: Tercer equipo: el fermentador
A2: Diseño del % de conversión para llegar a ≤0,5 % v/v de alcohol
A4: Datos del mosto y objetivo de diseño
A6: Variable | B6: Valor | C6: Unidad | D6: Nota
A7: Glucosa en el mosto | B7: ='Balance de materia'!B18 -> 10.2 | C7: kg | D7: Traído de la pestaña 'Balance de materia' (Glucosa)
A8: Maltosa en el mosto | B8: ='Balance de materia'!B17 -> 49.8 | C8: kg | D8: Traído de la pestaña 'Balance de materia' (Maltosa)
A9: Volumen del mosto | B9: ='Balance de materia'!B7 -> 600 | C9: L | D9: El volumen del fermentador (pestaña 'Balance de materia')
A10: Rendimiento etanol/azúcar (estequiometría) | B10: 0.53 | C10: kg/kg | D10: Promedio de las dos reacciones de conversión (glucosa y maltosa)
A11: Densidad del etanol | B11: 0.789 | C11: kg/L
A12: % v/v de alcohol objetivo | B12: 0.005 | C12: % v/v | D12: CAA Art. 1080: cerveza sin alcohol ≤ 0,5% v/v
A14: Cálculo de diseño
A16: Resultado | B16: Valor | C16: Unidad | D16: Fórmula
A17: Azúcar total (glucosa + maltosa) | B17: =B7+B8 -> 60 | C17: kg
A18: Etanol a 100% de conversión | B18: =B17*B10 -> 31.8 | C18: kg
A19: P objetivo (concentración de etanol) | B19: =B12*B11*1000 -> 3.945 | C19: g/L
A20: Etanol objetivo (masa) | B20: =B19*B9/1000 -> 2.367 | C20: kg
A21: CONVERSIÓN NECESARIA | B21: =IFERROR(B20/B18,"") -> 0.074433962 | C21: % | D21: Cargá este valor en el campo 'Conversion [%]' de las dos reacciones, en DWSIM
A23: Verificación con el resultado de DWSIM
A25: Variable | B25: Valor | C25: Unidad | D25: Nota
A26: Conversion [%] realmente usado en DWSIM | B26: 0
A27: Etanol resultante en la corriente 'cerveza' (DWSIM) | B27: 0 | C27: kg
A28: % v/v resultante | B28: =IF(B27=0,"",IFERROR((B27/B11)/B9*100,""))
A29: ¿Cumple ≤ 0,5 % v/v? | B29: =IF(B28="","",IF(B28<=B12,"Sí","No — bajá el Conversion% y volvé a correr"))

Sheet Comparación DWSIM
A1: Resumen: manual vs. DWSIM
A2: Para el entregable — completá las pestañas anteriores primero
A4: Equipo / resultado | B4: Cálculo manual | C4: DWSIM | D4: % diferencia
A5: Bomba — ΔT (°C) | B5: =Bomba!B20 -> 0.0093088444 | C5: =Bomba!C28 -> 0 | D5: =IF(C5=0,"",IFERROR((C5-B5)/B5,""))
A6: Bomba — Power (kW) | B6: =Bomba!B21 -> 0.069583612 | C6: =Bomba!C29 -> 0 | D6: =IF(C6=0,"",IFERROR((C6-B6)/B6,""))
A7: Bomba — NPSH (m) | B7: =Bomba!B23 -> 10.110537 | C7: =Bomba!C30 -> 0 | D7: =IF(C7=0,"",IFERROR((C7-B7)/B7,""))
A8: Intercambiador — Calor retirado (kJ) | B8: =Intercambiador!B17 -> 192000 | C8: =Intercambiador!C24 -> 0 | D8: =IF(C8=0,"",IFERROR((C8-B8)/B8,""))
A9: Fermentador — Conversion [%] | B9: =Fermentador!B21 -> 0.074433962 | C9: =Fermentador!B26 -> 0 | D9: =IF(C9=0,"",IFERROR((C9-B9)/B9,""))
A11: Completá primero los valores de DWSIM en las pestañas Bomba, Intercambiador y Fermentador — esta tabla se arma sola con esos datos. Si algún % de diferencia sale muy grande, revisá el dato de entrada correspondiente antes de asumir que el simulador está mal.
